Workbook

Sheet Cover
B2: LogiChain 2025 - Base-Case Financial Model
B3: Baseline COGS của FB_SET_001 (Front Brake Assembly) TRƯỚC khi có thông báo tăng giá
B4: Version v1.0 - Base case · Nguồn: LogiChain 2025 Data Case Study Hackathon (LOGin to LogiChain)
B6: Kết quả chính (Base case)
B7: COGS mỗi bộ (USD/set) | C7: =Summary!C7 -> 280.4
B8: Sản lượng base (bộ/tháng) | C8: =Summary!C8 -> 20400
B9: COGS tháng (USD) | C9: =Summary!C10 -> 5720160
B10: COGS năm (USD) | C10: =Summary!C11 -> 68641920
B11: NVL lớn nhất - % COGS | C11: =INDEX(Summary!C36:C43,MATCH(1,Summary!G36:G43,0))&" - "&TEXT(MAX(Summary!F36:F43),"0.0%") -> Steel Alloy - 57.6%
B12: NCC lớn nhất - % COGS | C12: =INDEX(Summary!B48:B54,MATCH(1,Summary!G48:G54,0))&" - "&TEXT(MAX(Summary!F48:F54),"0.0%") -> SteelCorp Ltd. - 53.5%
B13: Quốc gia phụ thuộc nhiều nhất - % COGS | C13: =INDEX(Summary!B59:B61,MATCH(1,Summary!G59:G61,0))&" - "&TEXT(MAX(Summary!F59:F61),"0.0%") -> Japan - 64.3%
B14: Trạng thái kiểm tra mô hình | C14: =Checks!C3 -> OK
B16: Cấu trúc file
B17: =HYPERLINK("#'Summary'!A1","Summary") -> Summary | C17: Kết quả: COGS/bộ, COGS tháng/năm, cơ cấu theo linh kiện - NVL - NCC - quốc gia, độ nhạy giá, memo hao hụt & công suất
B18: =HYPERLINK("#'Assumptions'!A1","Assumptions") -> Assumptions | C18: Mọi giả định & đòn bẩy giá (price levers = 0% ở base case), sản lượng, bước độ nhạy
B19: =HYPERLINK("#'BOM Cost Build-up'!A1","BOM Cost Build-up") -> BOM Cost Build-up | C19: Roll-up chi phí Level 1 (linh kiện) và Level 2 (NVL) từ sheet BOM & COGS Ratio
B20: =HYPERLINK("#'RM & Supplier Cost'!A1","RM & Supplier Cost") -> RM & Supplier Cost | C20: Phân bổ COGS theo NVL, NCC (supply ratio x đơn giá) và quốc gia xuất xứ
B21: =HYPERLINK("#'Capacity Check'!A1","Capacity Check") -> Capacity Check | C21: Memo: sản lượng base so với công suất hiệu dụng từng line
B22: =HYPERLINK("#'Checks'!A1","Checks") -> Checks | C22: 12 kiểm tra tính nhất quán dữ liệu & mô hình
B23: =HYPERLINK("#'BOM & COGS Ratio'!A1","BOM & COGS Ratio") -> BOM & COGS Ratio | C23: Dữ liệu gốc (giữ nguyên) - cùng 3 sheet dữ liệu gốc còn lại
B25: Quy ước màu
B26: 1,234 | C26: Chữ xanh dương = input nhập tay / đòn bẩy kịch bản
B27: 1,234 | C27: Chữ xanh lá = công thức lấy dữ liệu từ sheet khác
B28: 1,234 | C28: Chữ đen = công thức tính trong cùng sheet
B29: 1,234 | C29: Nền vàng = giả định chính / ô cần điền khi có thông tin mới
B31: Phương pháp & giả định chính
B32: 1. COGS/bộ = Σ COGS Value (USD) của 16 linh kiện Level 1. COGS Value đã bao gồm số lượng/bộ (kiểm chứng: COGS Ratio của đề = COGS Value / tổng).
B33: 2. Level 2 phân rã 100% COGS của linh kiện cha thành NVL (COGS NVL = Ratio x COGS cha) => toàn bộ COGS được coi là do NVL quyết định (đề không tách nhân công / overhead).
B34: 3. NVL nhiều nhà cung cấp: phân bổ giá trị theo value share = supply ratio x đơn giá / Σ(supply ratio x đơn giá).
B35: 4. Kịch bản giá: COGS NVL mới = COGS base x (giá bình quân gia quyền mới / giá bình quân gia quyền base). Base case: mọi price change = 0% => Scenario = Base.
B36: 5. Sản lượng base = Monthly capacity L0 x Utilization L0 = 24,000 x 85% = 20,400 bộ/tháng; 12 tháng/năm. Có ô override nếu đề cho nhu cầu thực tế.
B37: 6. Tỷ lệ hao hụt (waste) KHÔNG đưa vào base COGS (giữ đúng số liệu BOM); chỉ trình bày ở dạng memo.
B38: 7. OEE không dùng để tính sản lượng vì Utilization (theo định nghĩa của đề) đã phản ánh mức sử dụng thực tế.
B40: Khi có thông báo tăng giá
B41: Mở sheet Assumptions, mục C: nhập % tăng giá vào cột H (Price Change vs Base) cho đúng NCC / NVL (10% = 0.10). Nếu đề cho giá mới dạng USD/pc: % = giá mới / giá cũ - 1.
B42: Summary tự tính cột Scenario và Δ; cột Base Case giữ nguyên làm mốc so sánh. Bảng độ nhạy (mục 6 của Summary) cho biết trước mức tác động khi từng NCC tăng giá 5-20%.

Sheet Summary
A1: Base-Case Summary - FB_SET_001 Front Brake Assembly
A2: Baseline before the price-increase announcement · USD · per set and monthly / annual run-rate
B3: =IF(SUMPRODUCT(ABS(Assumptions!$H$20:$H$30))=0,"Status: BASE CASE - all price levers = 0% (Scenario = Base)","Status: PRICE LEVERS ACTIVE - Scenario column differs from Base") -> Status: BASE CASE - all price levers = 0% (Scenario = Base)
A5: 1. Key Metrics
B6: Metric | C6: Base Case | D6: Scenario (price levers) | E6: Δ vs Base | F6: Δ %
B7: COGS per set (USD) | C7: ='BOM Cost Build-up'!G22 -> 280.4 | D7: ='BOM Cost Build-up'!P22 -> 280.4 | E7: =D7-C7 -> 0 | F7: =IF(C7=0,0,E7/C7) -> 0
B8: Monthly output (sets) | C8: =Assumptions!$C$15 -> 20400 | D8: =Assumptions!$C$15 -> 20400 | E8: =D8-C8 -> 0 | F8: =IF(C8=0,0,E8/C8) -> 0
B9: Annual output (sets) | C9: =Assumptions!$C$16 -> 244800 | D9: =Assumptions!$C$16 -> 244800 | E9: =D9-C9 -> 0 | F9: =IF(C9=0,0,E9/C9) -> 0
B10: Monthly COGS (USD) | C10: =C7*C8 -> 5720160 | D10: =D7*D8 -> 5720160 | E10: =D10-C10 -> 0 | F10: =IF(C10=0,0,E10/C10) -> 0
B11: Annual COGS (USD) | C11: =C7*C9 -> 68641920 | D11: =D7*D9 -> 68641920 | E11: =D11-C11 -> 0 | F11: =IF(C11=0,0,E11/C11) -> 0
B12: Model checks | C12: =Checks!$C$3 -> OK
A14: 2. COGS Structure by Component (Level 1)
A15: # | B15: Part Code | C15: Part Name | D15: Qty / Set | E15: COGS (USD/set) | F15: % of COGS | G15: Rank | H15: Annual COGS (USD) | I15: Scenario (USD/set) | J15: Δ vs Base (USD/set)
A16: 1 | B16: ='BOM Cost Build-up'!B6 -> FB-001 | C16: ='BOM Cost Build-up'!C6 -> Hose Caliper Front LH | D16: ='BOM Cost Build-up'!D6 -> 1 | E16: ='BOM Cost Build-up'!G6 -> 12 | F16: =IF($E$32=0,0,E16/$E$32) -> 0.042796006 | G16: =RANK(E16,$E$16:$E$31) -> 8 | H16: =E16*Assumptions!$C$16 -> 2937600 | I16: ='BOM Cost Build-up'!P6 -> 12 | J16: =I16-E16 -> 0
A17: 2 | B17: ='BOM Cost Build-up'!B7 -> FB-002 | C17: ='BOM Cost Build-up'!C7 -> Hose Caliper Front RH | D17: ='BOM Cost Build-up'!D7 -> 1 | E17: ='BOM Cost Build-up'!G7 -> 12 | F17: =IF($E$32=0,0,E17/$E$32) -> 0.042796006 | G17: =RANK(E17,$E$16:$E$31) -> 8 | H17: =E17*Assumptions!$C$16 -> 2937600 | I17: ='BOM Cost Build-up'!P7 -> 12 | J17: =I17-E17 -> 0
A18: 3 | B18: ='BOM Cost Build-up'!B8 -> FB-003 | C18: ='BOM Cost Build-up'!C8 -> Seal - Brass Hydraulic | D18: ='BOM Cost Build-up'!D8 -> 4 | E18: ='BOM Cost Build-up'!G8 -> 6 | F18: =IF($E$32=0,0,E18/$E$32) -> 0.021398003 | G18: =RANK(E18,$E$16:$E$31) -> 10 | H18: =E18*Assumptions!$C$16 -> 1468800 | I18: ='BOM Cost Build-up'!P8 -> 6 | J18: =I18-E18 -> 0
A19: 4 | B19: ='BOM Cost Build-up'!B9 -> FB-004 | C19: ='BOM Cost Build-up'!C9 -> Retain Clip Hose Frame Attach | D19: ='BOM Cost Build-up'!D9 -> 2 | E19: ='BOM Cost Build-up'!G9 -> 1 | F19: =IF($E$32=0,0,E19/$E$32) -> 0.0035663338 | G19: =RANK(E19,$E$16:$E$31) -> 14 | H19: =E19*Assumptions!$C$16 -> 244800 | I19: ='BOM Cost Build-up'!P9 -> 1 | J19: =I19-E19 -> 0
A20: 5 | B20: ='BOM Cost Build-up'!B10 -> FB-005 | C20: ='BOM Cost Build-up'!C10 -> Stainless Brake Lines | D20: ='BOM Cost Build-up'!D10 -> 2 | E20: ='BOM Cost Build-up'!G10 -> 16 | F20: =IF($E$32=0,0,E20/$E$32) -> 0.057061341 | G20: =RANK(E20,$E$16:$E$31) -> 7 | H20: =E20*Assumptions!$C$16 -> 3916800 | I20: ='BOM Cost Build-up'!P10 -> 16 | J20: =I20-E20 -> 0
A21: 6 | B21: ='BOM Cost Build-up'!B11 -> FB-006 | C21: ='BOM Cost Build-up'!C11 -> Caliper Disc Front LH | D21: ='BOM Cost Build-up'!D11 -> 1 | E21: ='BOM Cost Build-up'!G11 -> 50 | F21: =IF($E$32=0,0,E21/$E$32) -> 0.17831669 | G21: =RANK(E21,$E$16:$E$31) -> 1 | H21: =E21*Assumptions!$C$16 -> 12240000 | I21: ='BOM Cost Build-up'!P11 -> 50 | J21: =I21-E21 -> 0
A22: 7 | B22: ='BOM Cost Build-up'!B12 -> FB-007 | C22: ='BOM Cost Build-up'!C12 -> Caliper Disc Front RH | D22: ='BOM Cost Build-up'!D12 -> 1 | E22: ='BOM Cost Build-up'!G12 -> 50 | F22: =IF($E$32=0,0,E22/$E$32) -> 0.17831669 | G22: =RANK(E22,$E$16:$E$31) -> 1 | H22: =E22*Assumptions!$C$16 -> 12240000 | I22: ='BOM Cost Build-up'!P12 -> 50 | J22: =I22-E22 -> 0
A23: 8 | B23: ='BOM Cost Build-up'!B13 -> FB-008 | C23: ='BOM Cost Build-up'!C13 -> Rotor Disc Brake | D23: ='BOM Cost Build-up'!D13 -> 2 | E23: ='BOM Cost Build-up'!G13 -> 50 | F23: =IF($E$32=0,0,E23/$E$32) -> 0.17831669 | G23: =RANK(E23,$E$16:$E$31) -> 1 | H23: =E23*Assumptions!$C$16 -> 12240000 | I23: ='BOM Cost Build-up'!P13 -> 50 | J23: =I23-E23 -> 0
A24: 9 | B24: ='BOM Cost Build-up'!B14 -> FB-009 | C24: ='BOM Cost Build-up'!C14 -> Bearing Inner Wheel | D24: ='BOM Cost Build-up'!D14 -> 2 | E24: ='BOM Cost Build-up'!G14 -> 20 | F24: =IF($E$32=0,0,E24/$E$32) -> 0.071326676 | G24: =RANK(E24,$E$16:$E$31) -> 5 | H24: =E24*Assumptions!$C$16 -> 4896000 | I24: ='BOM Cost Build-up'!P14 -> 20 | J24: =I24-E24 -> 0
A25: 10 | B25: ='BOM Cost Build-up'!B15 -> FB-010 | C25: ='BOM Cost Build-up'!C15 -> Bearing Outer Wheel | D25: ='BOM Cost Build-up'!D15 -> 2 | E25: ='BOM Cost Build-up'!G15 -> 20 | F25: =IF($E$32=0,0,E25/$E$32) -> 0.071326676 | G25: =RANK(E25,$E$16:$E$31) -> 5 | H25: =E25*Assumptions!$C$16 -> 4896000 | I25: ='BOM Cost Build-up'!P15 -> 20 | J25: =I25-E25 -> 0
A26: 11 | B26: ='BOM Cost Build-up'!B16 -> FB-011 | C26: ='BOM Cost Build-up'!C16 -> Washer Retainer Outer Bearing | D26: ='BOM Cost Build-up'!D16 -> 2 | E26: ='BOM Cost Build-up'!G16 -> 1 | F26: =IF($E$32=0,0,E26/$E$32) -> 0.0035663338 | G26: =RANK(E26,$E$16:$E$31) -> 14 | H26: =E26*Assumptions!$C$16 -> 244800 | I26: ='BOM Cost Build-up'!P16 -> 1 | J26: =I26-E26 -> 0
A27: 12 | B27: ='BOM Cost Build-up'!B17 -> FB-012 | C27: ='BOM Cost Build-up'!C17 -> Cotter Key | D27: ='BOM Cost Build-up'!D17 -> 2 | E27: ='BOM Cost Build-up'!G17 -> 0.4 | F27: =IF($E$32=0,0,E27/$E$32) -> 0.0014265335 | G27: =RANK(E27,$E$16:$E$31) -> 16 | H27: =E27*Assumptions!$C$16 -> 97920 | I27: ='BOM Cost Build-up'!P17 -> 0.4 | J27: =I27-E27 -> 0
... A31: 16 | B31: ='BOM Cost Build-up'!B21 -> FB-016 | C31: ='BOM Cost Build-up'!C21 -> Tube Hyd Front Distribution | D31: ='BOM Cost Build-up'!D21 -> 1 | E31: ='BOM Cost Build-up'!G21 -> 6 | F31: =IF($E$32=0,0,E31/$E$32) -> 0.021398003 | G31: =RANK(E31,$E$16:$E$31) -> 10 | H31: =E31*Assumptions!$C$16 -> 1468800 | I31: ='BOM Cost Build-up'!P21 -> 6 | J31: =I31-E31 -> 0
B32: Total | E32: =SUM(E16:E31) -> 280.4 | F32: =SUM(F16:F31) -> 1 | H32: =SUM(H16:H31) -> 68641920 | I32: =SUM(I16:I31) -> 280.4 | J32: =SUM(J16:J31) -> 0
A34: 3. COGS Structure by Raw Material (Level 2)
A35: # | B35: Material Code | C35: Material Name | D35: # Suppliers | E35: COGS (USD/set) | F35: % of COGS | G35: Rank | H35: Annual COGS (USD) | I35: Scenario (USD/set) | J35: Δ vs Base (USD/set)
A36: 1 | B36: ='RM & Supplier Cost'!B6 -> RM-SS-TUBE-316L | C36: ='RM & Supplier Cost'!C6 -> Stainless Steel | D36: ='RM & Supplier Cost'!E6 -> 3 | E36: ='RM & Supplier Cost'!G6 -> 31.5064 | F36: =IF($E$44=0,0,E36/$E$44) -> 0.11236234 | G36: =RANK(E36,$E$36:$E$43) -> 3 | H36: =E36*Assumptions!$C$16 -> 7712766.7 | I36: ='RM & Supplier Cost'!L6 -> 31.5064 | J36: =I36-E36 -> 0
A37: 2 | B37: ='RM & Supplier Cost'!B7 -> RM-RUBBER-EPDM/NBR | C37: ='RM & Supplier Cost'!C7 -> Synthetic Rubber | D37: ='RM & Supplier Cost'!E7 -> 1 | E37: ='RM & Supplier Cost'!G7 -> 18.6652 | F37: =IF($E$44=0,0,E37/$E$44) -> 0.066566334 | G37: =RANK(E37,$E$36:$E$43) -> 5 | H37: =E37*Assumptions!$C$16 -> 4569241 | I37: ='RM & Supplier Cost'!L7 -> 18.6652 | J37: =I37-E37 -> 0
A38: 3 | B38: ='RM & Supplier Cost'!B8 -> RM-BRASS | C38: ='RM & Supplier Cost'!C8 -> Brass | D38: ='RM & Supplier Cost'!E8 -> 1 | E38: ='RM & Supplier Cost'!G8 -> 3.8586 | F38: =IF($E$44=0,0,E38/$E$44) -> 0.013761056 | G38: =RANK(E38,$E$36:$E$43) -> 6 | H38: =E38*Assumptions!$C$16 -> 944585.28 | I38: ='RM & Supplier Cost'!L8 -> 3.8586 | J38: =I38-E38 -> 0
A39: 4 | B39: ='RM & Supplier Cost'!B9 -> RM-STEEL-ALLOY | C39: ='RM & Supplier Cost'!C9 -> Steel Alloy | D39: ='RM & Supplier Cost'!E9 -> 2 | E39: ='RM & Supplier Cost'!G9 -> 161.454 | F39: =IF($E$44=0,0,E39/$E$44) -> 0.57579886 | G39: =RANK(E39,$E$36:$E$43) -> 1 | H39: =E39*Assumptions!$C$16 -> 39523939 | I39: ='RM & Supplier Cost'!L9 -> 161.454 | J39: =I39-E39 -> 0
A40: 5 | B40: ='RM & Supplier Cost'!B10 -> RM-BEARING-STEEL | C40: ='RM & Supplier Cost'!C10 -> Bearing Steel | D40: ='RM & Supplier Cost'!E10 -> 1 | E40: ='RM & Supplier Cost'!G10 -> 40 | F40: =IF($E$44=0,0,E40/$E$44) -> 0.14265335 | G40: =RANK(E40,$E$36:$E$43) -> 2 | H40: =E40*Assumptions!$C$16 -> 9792000 | I40: ='RM & Supplier Cost'!L10 -> 40 | J40: =I40-E40 -> 0
A41: 6 | B41: ='RM & Supplier Cost'!B11 -> RM-GREASE | C41: ='RM & Supplier Cost'!C11 -> High Temp Grease | D41: ='RM & Supplier Cost'!E11 -> 1 | E41: ='RM & Supplier Cost'!G11 -> 2.7816 | F41: =IF($E$44=0,0,E41/$E$44) -> 0.0099201141 | G41: =RANK(E41,$E$36:$E$43) -> 7 | H41: =E41*Assumptions!$C$16 -> 680935.68 | I41: ='RM & Supplier Cost'!L11 -> 2.7816 | J41: =I41-E41 -> 0
A42: 7 | B42: ='RM & Supplier Cost'!B12 -> RM-PLASTIC-POM | C42: ='RM & Supplier Cost'!C12 -> Engineering Plastic | D42: ='RM & Supplier Cost'!E12 -> 1 | E42: ='RM & Supplier Cost'!G12 -> 1.1882 | F42: =IF($E$44=0,0,E42/$E$44) -> 0.0042375178 | G42: =RANK(E42,$E$36:$E$43) -> 8 | H42: =E42*Assumptions!$C$16 -> 290871.36 | I42: ='RM & Supplier Cost'!L12 -> 1.1882 | J42: =I42-E42 -> 0
A43: 8 | B43: ='RM & Supplier Cost'!B13 -> RM-FRICTION-MAT | C43: ='RM & Supplier Cost'!C13 -> Friction Material | D43: ='RM & Supplier Cost'!E13 -> 1 | E43: ='RM & Supplier Cost'!G13 -> 20.946 | F43: =IF($E$44=0,0,E43/$E$44) -> 0.074700428 | G43: =RANK(E43,$E$36:$E$43) -> 4 | H43: =E43*Assumptions!$C$16 -> 5127580.8 | I43: ='RM & Supplier Cost'!L13 -> 20.946 | J43: =I43-E43 -> 0
B44: Total | E44: =SUM(E36:E43) -> 280.4 | F44: =SUM(F36:F43) -> 1 | H44: =SUM(H36:H43) -> 68641920 | I44: =SUM(I36:I43) -> 280.4 | J44: =SUM(J36:J43) -> 0
A46: 4. COGS by Supplier
A47: # | B47: Supplier | C47: Origin | D47: # Materials | E47: COGS (USD/set) | F47: % of COGS | G47: Rank | H47: Annual Spend (USD) | I47: Scenario (USD/set) | J47: Δ vs Base (USD/set)
...

Sheet Assumptions
A1: Assumptions & Inputs
A2: Base case = supplier prices before any price-increase announcement (all price levers = 0%). Blue = input · Green = link to another sheet · Black = formula · Yellow = key assumption
A4: A. General
B5: Currency | C5: USD | E5: All costs in the case data are quoted in USD
B6: Product item code | C6: ='BOM & COGS Ratio'!I3 -> FB_SET_001 | E6: Source: BOM & COGS Ratio, Product Item Code
B7: Product name | C7: ='Factory Information'!C3 -> Front Brake Assembly | E7: Source: Factory Information, Line L0
B8: Months per year | C8: 12 | D8: months | E8: Assumption: 12-month run-rate (no seasonality / demand data in the dataset)
A10: B. Production Volume
B11: L0 assembly line - monthly capacity | C11: ='Factory Information'!E3 -> 24000 | D11: sets/month | E11: Source: Factory Information, Line L0 (FB_SET_001 Front Brake Assembly)
B12: L0 assembly line - utilization | C12: ='Factory Information'!G3 -> 0.85 | D12: % | E12: Source: Factory Information (capacity actually utilized vs. maximum capacity)
B13: Calculated monthly output | C13: =C11*C12 -> 20400 | D13: sets/month | E13: Capacity x Utilization (OEE not applied: utilization already reflects actual output)
B14: Monthly output override (optional) | D14: sets/month | E14: Leave blank to use calculated output; enter the demand figure here if the case brief gives one
B15: Base-case monthly output (used) | C15: =IF(ISNUMBER(C14),C14,C13) -> 20400 | D15: sets/month | E15: Key assumption - drives monthly / annual COGS and material requirements
B16: Base-case annual output | C16: =C15*C8 -> 244800 | D16: sets/year
A18: C. Raw-Material Supplier Prices & Price-Change Levers
A19: # | B19: Material Code | C19: Material Name | D19: Supplier | E19: Origin | F19: Supply Ratio | G19: Base Unit Price (USD/pc) | H19: Price Change vs Base | I19: Scenario Unit Price (USD/pc) | J19: Source
A20: 1 | B20: ='Supplier Profile'!A3 -> RM-SS-TUBE-316L | C20: ='Supplier Profile'!B3 -> Stainless Steel | D20: ='Supplier Profile'!C3 -> SteelCorp Ltd. | E20: ='Supplier Profile'!D3 -> Japan | F20: ='Supplier Profile'!E3 -> 0.4 | G20: ='Supplier Profile'!I3 -> 4.2 | H20: 0 | I20: =G20*(1+H20) -> 4.2 | J20: Supplier Profile row 3
A21: 2 | B21: ='Supplier Profile'!A3 -> RM-SS-TUBE-316L | C21: ='Supplier Profile'!B3 -> Stainless Steel | D21: ='Supplier Profile'!C4 -> Nihon Metal Works | E21: ='Supplier Profile'!D4 -> Japan | F21: ='Supplier Profile'!E4 -> 0.3 | G21: ='Supplier Profile'!I4 -> 4.1 | H21: 0 | I21: =G21*(1+H21) -> 4.1 | J21: Supplier Profile row 4
A22: 3 | B22: ='Supplier Profile'!A3 -> RM-SS-TUBE-316L | C22: ='Supplier Profile'!B3 -> Stainless Steel | D22: ='Supplier Profile'!C5 -> GlobalSteel Industries | E22: ='Supplier Profile'!D5 -> South Korea | F22: ='Supplier Profile'!E5 -> 0.3 | G22: ='Supplier Profile'!I5 -> 4.15 | H22: 0 | I22: =G22*(1+H22) -> 4.15 | J22: Supplier Profile row 5
A23: 4 | B23: ='Supplier Profile'!A6 -> RM-RUBBER-EPDM/NBR | C23: ='Supplier Profile'!B6 -> Synthetic Rubber | D23: ='Supplier Profile'!C6 -> PolyRubber Inc. | E23: ='Supplier Profile'!D6 -> Vietnam | F23: ='Supplier Profile'!E6 -> 1 | G23: ='Supplier Profile'!I6 -> 2.9 | H23: 0 | I23: =G23*(1+H23) -> 2.9 | J23: Supplier Profile row 6
A24: 5 | B24: ='Supplier Profile'!A7 -> RM-BRASS | C24: ='Supplier Profile'!B7 -> Brass | D24: ='Supplier Profile'!C7 -> MetalWorks Co. | E24: ='Supplier Profile'!D7 -> Vietnam | F24: ='Supplier Profile'!E7 -> 1 | G24: ='Supplier Profile'!I7 -> 3.6 | H24: 0 | I24: =G24*(1+H24) -> 3.6 | J24: Supplier Profile row 7
A25: 6 | B25: ='Supplier Profile'!A8 -> RM-STEEL-ALLOY | C25: ='Supplier Profile'!B8 -> Steel Alloy | D25: ='Supplier Profile'!C8 -> SteelCorp Ltd. | E25: ='Supplier Profile'!D8 -> Japan | F25: ='Supplier Profile'!E8 -> 0.6 | G25: ='Supplier Profile'!I8 -> 8.5 | H25: 0 | I25: =G25*(1+H25) -> 8.5 | J25: Supplier Profile row 8
A26: 7 | B26: ='Supplier Profile'!A8 -> RM-STEEL-ALLOY | C26: ='Supplier Profile'!B8 -> Steel Alloy | D26: ='Supplier Profile'!C9 -> GlobalSteel Industries | E26: ='Supplier Profile'!D9 -> South Korea | F26: ='Supplier Profile'!E9 -> 0.4 | G26: ='Supplier Profile'!I9 -> 8.4 | H26: 0 | I26: =G26*(1+H26) -> 8.4 | J26: Supplier Profile row 9
A27: 8 | B27: ='Supplier Profile'!A10 -> RM-BEARING-STEEL | C27: ='Supplier Profile'!B10 -> Bearing Steel | D27: ='Supplier Profile'!C10 -> SteelCorp Ltd. | E27: ='Supplier Profile'!D10 -> Japan | F27: ='Supplier Profile'!E10 -> 1 | G27: ='Supplier Profile'!I10 -> 9.5 | H27: 0 | I27: =G27*(1+H27) -> 9.5 | J27: Supplier Profile row 10
A28: 9 | B28: ='Supplier Profile'!A11 -> RM-GREASE | C28: ='Supplier Profile'!B11 -> High Temp Grease | D28: ='Supplier Profile'!C11 -> ChemLube Ltd. | E28: ='Supplier Profile'!D11 -> Vietnam | F28: ='Supplier Profile'!E11 -> 1 | G28: ='Supplier Profile'!I11 -> 2.5 | H28: 0 | I28: =G28*(1+H28) -> 2.5 | J28: Supplier Profile row 11
A29: 10 | B29: ='Supplier Profile'!A12 -> RM-PLASTIC-POM | C29: ='Supplier Profile'!B12 -> Engineering Plastic | D29: ='Supplier Profile'!C12 -> PolyRubber Inc. | E29: ='Supplier Profile'!D12 -> Vietnam | F29: ='Supplier Profile'!E12 -> 1 | G29: ='Supplier Profile'!I12 -> 1.1 | H29: 0 | I29: =G29*(1+H29) -> 1.1 | J29: Supplier Profile row 12
A30: 11 | B30: ='Supplier Profile'!A13 -> RM-FRICTION-MAT | C30: ='Supplier Profile'!B13 -> Friction Material | D30: ='Supplier Profile'!C13 -> FrictionTech Co. | E30: ='Supplier Profile'!D13 -> Japan | F30: ='Supplier Profile'!E13 -> 1 | G30: ='Supplier Profile'!I13 -> 19.5 | H30: 0 | I30: =G30*(1+H30) -> 19.5 | J30: Supplier Profile row 13
B31: Base case: every lever in column H stays at 0%. When a price increase is announced, enter it as a fraction (10% = 0.10) for the affected supplier / material; Base-case outputs stay frozen and the Scenario columns show the impact.
A33: D. Sensitivity Steps (price increase applied to one supplier)
B34: Price increase steps | C34: 0.05 | D34: 0.1 | E34: 0.15 | F34: 0.2 | G34: Used in Summary sensitivity table

Sheet BOM Cost Build-up
A1: BOM Cost Build-up - FB_SET_001 Front Brake Assembly
A2: Source: 'BOM & COGS Ratio' sheet. All values per 1 finished set. COGS Value already includes Qty per set (source ratio = COGS Value / total).
A4: 1. Level 1 - Components (per set)
A5: # | B5: Part Code | C5: Part Name | D5: Qty / Set | E5: Unit | F5: Production Line | G5: COGS Value (USD/set) | H5: Unit Cost (USD/pc) | I5: COGS Share (calc) | J5: COGS Ratio (source) | K5: |Diff| calc vs source | L5: Level-2 Roll-up (USD/set) | M5: |Diff| roll-up vs L1 | N5: Line Waste Rate | O5: Waste-adj. COGS (USD/set) - memo | P5: Scenario COGS (USD/set) | Q5: Δ vs Base (USD/set)
A6: 1 | B6: ='BOM & COGS Ratio'!B3 -> FB-001 | C6: ='BOM & COGS Ratio'!C3 -> Hose Caliper Front LH | D6: ='BOM & COGS Ratio'!E3 -> 1 | E6: ='BOM & COGS Ratio'!F3 -> pcs | F6: ='Factory Information'!A5 -> L2 | G6: ='BOM & COGS Ratio'!K3 -> 12 | H6: =IF(D6=0,0,G6/D6) -> 12 | I6: =IF($G$22=0,0,G6/$G$22) -> 0.042796006 | J6: ='BOM & COGS Ratio'!J3 -> 0.0428 | K6: =ROUND(ABS(I6-J6),6) -> 4e-06 | L6: =SUMIF($B$27:$B$48,B6,$H$27:$H$48) -> 12 | M6: =ROUND(ABS(L6-G6),6) -> 0 | N6: ='Factory Information'!H5 -> 0.03 | O6: =G6/(1-N6) -> 12.371134 | P6: =SUMIF($B$27:$B$48,B6,$L$27:$L$48) -> 12 | Q6: =P6-G6 -> 0
A7: 2 | B7: ='BOM & COGS Ratio'!B4 -> FB-002 | C7: ='BOM & COGS Ratio'!C4 -> Hose Caliper Front RH | D7: ='BOM & COGS Ratio'!E4 -> 1 | E7: ='BOM & COGS Ratio'!F4 -> pcs | F7: ='Factory Information'!A5 -> L2 | G7: ='BOM & COGS Ratio'!K4 -> 12 | H7: =IF(D7=0,0,G7/D7) -> 12 | I7: =IF($G$22=0,0,G7/$G$22) -> 0.042796006 | J7: ='BOM & COGS Ratio'!J4 -> 0.0428 | K7: =ROUND(ABS(I7-J7),6) -> 4e-06 | L7: =SUMIF($B$27:$B$48,B7,$H$27:$H$48) -> 12 | M7: =ROUND(ABS(L7-G7),6) -> 0 | N7: ='Factory Information'!H6 -> 0.035 | O7: =G7/(1-N7) -> 12.435233 | P7: =SUMIF($B$27:$B$48,B7,$L$27:$L$48) -> 12 | Q7: =P7-G7 -> 0
A8: 3 | B8: ='BOM & COGS Ratio'!B5 -> FB-003 | C8: ='BOM & COGS Ratio'!C5 -> Seal - Brass Hydraulic | D8: ='BOM & COGS Ratio'!E5 -> 4 | E8: ='BOM & COGS Ratio'!F5 -> pcs | F8: ='Factory Information'!A13 -> L8 | G8: ='BOM & COGS Ratio'!K5 -> 6 | H8: =IF(D8=0,0,G8/D8) -> 1.5 | I8: =IF($G$22=0,0,G8/$G$22) -> 0.021398003 | J8: ='BOM & COGS Ratio'!J5 -> 0.0214 | K8: =ROUND(ABS(I8-J8),6) -> 2e-06 | L8: =SUMIF($B$27:$B$48,B8,$H$27:$H$48) -> 6 | M8: =ROUND(ABS(L8-G8),6) -> 0 | N8: ='Factory Information'!H13 -> 0.04 | O8: =G8/(1-N8) -> 6.25 | P8: =SUMIF($B$27:$B$48,B8,$L$27:$L$48) -> 6 | Q8: =P8-G8 -> 0
A9: 4 | B9: ='BOM & COGS Ratio'!B6 -> FB-004 | C9: ='BOM & COGS Ratio'!C6 -> Retain Clip Hose Frame Attach | D9: ='BOM & COGS Ratio'!E6 -> 2 | E9: ='BOM & COGS Ratio'!F6 -> pcs | F9: ='Factory Information'!A14 -> L9 | G9: ='BOM & COGS Ratio'!K6 -> 1 | H9: =IF(D9=0,0,G9/D9) -> 0.5 | I9: =IF($G$22=0,0,G9/$G$22) -> 0.0035663338 | J9: ='BOM & COGS Ratio'!J6 -> 0.0036 | K9: =ROUND(ABS(I9-J9),6) -> 3.4e-05 | L9: =SUMIF($B$27:$B$48,B9,$H$27:$H$48) -> 1 | M9: =ROUND(ABS(L9-G9),6) -> 0 | N9: ='Factory Information'!H14 -> 0.02 | O9: =G9/(1-N9) -> 1.0204082 | P9: =SUMIF($B$27:$B$48,B9,$L$27:$L$48) -> 1 | Q9: =P9-G9 -> 0
A10: 5 | B10: ='BOM & COGS Ratio'!B7 -> FB-005 | C10: ='BOM & COGS Ratio'!C7 -> Stainless Brake Lines | D10: ='BOM & COGS Ratio'!E7 -> 2 | E10: ='BOM & COGS Ratio'!F7 -> pcs | F10: ='Factory Information'!A7 -> L3 | G10: ='BOM & COGS Ratio'!K7 -> 16 | H10: =IF(D10=0,0,G10/D10) -> 8 | I10: =IF($G$22=0,0,G10/$G$22) -> 0.057061341 | J10: ='BOM & COGS Ratio'!J7 -> 0.0571 | K10: =ROUND(ABS(I10-J10),6) -> 3.9e-05 | L10: =SUMIF($B$27:$B$48,B10,$H$27:$H$48) -> 16 | M10: =ROUND(ABS(L10-G10),6) -> 0 | N10: ='Factory Information'!H7 -> 0.02 | O10: =G10/(1-N10) -> 16.326531 | P10: =SUMIF($B$27:$B$48,B10,$L$27:$L$48) -> 16 | Q10: =P10-G10 -> 0
A11: 6 | B11: ='BOM & COGS Ratio'!B8 -> FB-006 | C11: ='BOM & COGS Ratio'!C8 -> Caliper Disc Front LH | D11: ='BOM & COGS Ratio'!E8 -> 1 | E11: ='BOM & COGS Ratio'!F8 -> pcs | F11: ='Factory Information'!A9 -> L5 | G11: ='BOM & COGS Ratio'!K8 -> 50 | H11: =IF(D11=0,0,G11/D11) -> 50 | I11: =IF($G$22=0,0,G11/$G$22) -> 0.17831669 | J11: ='BOM & COGS Ratio'!J8 -> 0.1783 | K11: =ROUND(ABS(I11-J11),6) -> 1.7e-05 | L11: =SUMIF($B$27:$B$48,B11,$H$27:$H$48) -> 50 | M11: =ROUND(ABS(L11-G11),6) -> 0 | N11: ='Factory Information'!H9 -> 0.024 | O11: =G11/(1-N11) -> 51.229508 | P11: =SUMIF($B$27:$B$48,B11,$L$27:$L$48) -> 50 | Q11: =P11-G11 -> 0
A12: 7 | B12: ='BOM & COGS Ratio'!B9 -> FB-007 | C12: ='BOM & COGS Ratio'!C9 -> Caliper Disc Front RH | D12: ='BOM & COGS Ratio'!E9 -> 1 | E12: ='BOM & COGS Ratio'!F9 -> pcs | F12: ='Factory Information'!A9 -> L5 | G12: ='BOM & COGS Ratio'!K9 -> 50 | H12: =IF(D12=0,0,G12/D12) -> 50 | I12: =IF($G$22=0,0,G12/$G$22) -> 0.17831669 | J12: ='BOM & COGS Ratio'!J9 -> 0.1783 | K12: =ROUND(ABS(I12-J12),6) -> 1.7e-05 | L12: =SUMIF($B$27:$B$48,B12,$H$27:$H$48) -> 50 | M12: =ROUND(ABS(L12-G12),6) -> 0 | N12: ='Factory Information'!H10 -> 0.026 | O12: =G12/(1-N12) -> 51.334702 | P12: =SUMIF($B$27:$B$48,B12,$L$27:$L$48) -> 50 | Q12: =P12-G12 -> 0
A13: 8 | B13: ='BOM & COGS Ratio'!B10 -> FB-008 | C13: ='BOM & COGS Ratio'!C10 -> Rotor Disc Brake | D13: ='BOM & COGS Ratio'!E10 -> 2 | E13: ='BOM & COGS Ratio'!F10 -> pcs | F13: ='Factory Information'!A4 -> L1 | G13: ='BOM & COGS Ratio'!K10 -> 50 | H13: =IF(D13=0,0,G13/D13) -> 25 | I13: =IF($G$22=0,0,G13/$G$22) -> 0.17831669 | J13: ='BOM & COGS Ratio'!J10 -> 0.1783 | K13: =ROUND(ABS(I13-J13),6) -> 1.7e-05 | L13: =SUMIF($B$27:$B$48,B13,$H$27:$H$48) -> 50 | M13: =ROUND(ABS(L13-G13),6) -> 0 | N13: ='Factory Information'!H4 -> 0.025 | O13: =G13/(1-N13) -> 51.282051 | P13: =SUMIF($B$27:$B$48,B13,$L$27:$L$48) -> 50 | Q13: =P13-G13 -> 0
A14: 9 | B14: ='BOM & COGS Ratio'!B11 -> FB-009 | C14: ='BOM & COGS Ratio'!C11 -> Bearing Inner Wheel | D14: ='BOM & COGS Ratio'!E11 -> 2 | E14: ='BOM & COGS Ratio'!F11 -> pcs | F14: ='Factory Information'!A11 -> L6 | G14: ='BOM & COGS Ratio'!K11 -> 20 | H14: =IF(D14=0,0,G14/D14) -> 10 | I14: =IF($G$22=0,0,G14/$G$22) -> 0.071326676 | J14: ='BOM & COGS Ratio'!J11 -> 0.0713 | K14: =ROUND(ABS(I14-J14),6) -> 2.7e-05 | L14: =SUMIF($B$27:$B$48,B14,$H$27:$H$48) -> 20 | M14: =ROUND(ABS(L14-G14),6) -> 0 | N14: ='Factory Information'!H11 -> 0.031 | O14: =G14/(1-N14) -> 20.639835 | P14: =SUMIF($B$27:$B$48,B14,$L$27:$L$48) -> 20 | Q14: =P14-G14 -> 0
A15: 10 | B15: ='BOM & COGS Ratio'!B12 -> FB-010 | C15: ='BOM & COGS Ratio'!C12 -> Bearing Outer Wheel | D15: ='BOM & COGS Ratio'!E12 -> 2 | E15: ='BOM & COGS Ratio'!F12 -> pcs | F15: ='Factory Information'!A12 -> L7 | G15: ='BOM & COGS Ratio'!K12 -> 20 | H15: =IF(D15=0,0,G15/D15) -> 10 | I15: =IF($G$22=0,0,G15/$G$22) -> 0.071326676 | J15: ='BOM & COGS Ratio'!J12 -> 0.0713 | K15: =ROUND(ABS(I15-J15),6) -> 2.7e-05 | L15: =SUMIF($B$27:$B$48,B15,$H$27:$H$48) -> 20 | M15: =ROUND(ABS(L15-G15),6) -> 0 | N15: ='Factory Information'!H12 -> 0.045 | O15: =G15/(1-N15) -> 20.942408 | P15: =SUMIF($B$27:$B$48,B15,$L$27:$L$48) -> 20 | Q15: =P15-G15 -> 0
A16: 11 | B16: ='BOM & COGS Ratio'!B13 -> FB-011 | C16: ='BOM & COGS Ratio'!C13 -> Washer Retainer Outer Bearing | D16: ='BOM & COGS Ratio'!E13 -> 2 | E16: ='BOM & COGS Ratio'!F13 -> pcs | F16: ='Factory Information'!A17 -> L12 | G16: ='BOM & COGS Ratio'!K13 -> 1 | H16: =IF(D16=0,0,G16/D16) -> 0.5 | I16: =IF($G$22=0,0,G16/$G$22) -> 0.0035663338 | J16: ='BOM & COGS Ratio'!J13 -> 0.0036 | K16: =ROUND(ABS(I16-J16),6) -> 3.4e-05 | L16: =SUMIF($B$27:$B$48,B16,$H$27:$H$48) -> 1 | M16: =ROUND(ABS(L16-G16),6) -> 0 | N16: ='Factory Information'!H17 -> 0.027 | O16: =G16/(1-N16) -> 1.0277492 | P16: =SUMIF($B$27:$B$48,B16,$L$27:$L$48) -> 1 | Q16: =P16-G16 -> 0
A17: 12 | B17: ='BOM & COGS Ratio'!B14 -> FB-012 | C17: ='BOM & COGS Ratio'!C14 -> Cotter Key | D17: ='BOM & COGS Ratio'!E14 -> 2 | E17: ='BOM & COGS Ratio'!F14 -> pcs | F17: ='Factory Information'!A18 -> L13 | G17: ='BOM & COGS Ratio'!K14 -> 0.4 | H17: =IF(D17=0,0,G17/D17) -> 0.2 | I17: =IF($G$22=0,0,G17/$G$22) -> 0.0014265335 | J17: ='BOM & COGS Ratio'!J14 -> 0.0014 | K17: =ROUND(ABS(I17-J17),6) -> 2.7e-05 | L17: =SUMIF($B$27:$B$48,B17,$H$27:$H$48) -> 0.4 | M17: =ROUND(ABS(L17-G17),6) -> 0 | N17: ='Factory Information'!H18 -> 0.025 | O17: =G17/(1-N17) -> 0.41025641 | P17: =SUMIF($B$27:$B$48,B17,$L$27:$L$48) -> 0.4 | Q17: =P17-G17 -> 0
A18: 13 | B18: ='BOM & COGS Ratio'!B15 -> FB-013 | C18: ='BOM & COGS Ratio'!C15 -> Seal Grease | D18: ='BOM & COGS Ratio'!E15 -> 2 | E18: ='BOM & COGS Ratio'!F15 -> pcs | F18: ='Factory Information'!A19 -> L14 | G18: ='BOM & COGS Ratio'!K15 -> 4 | H18: =IF(D18=0,0,G18/D18) -> 2 | I18: =IF($G$22=0,0,G18/$G$22) -> 0.014265335 | J18: ='BOM & COGS Ratio'!J15 -> 0.0143 | K18: =ROUND(ABS(I18-J18),6) -> 3.5e-05 | L18: =SUMIF($B$27:$B$48,B18,$H$27:$H$48) -> 4 | M18: =ROUND(ABS(L18-G18),6) -> 0 | N18: ='Factory Information'!H19 -> 0.025 | O18: =G18/(1-N18) -> 4.1025641 | P18: =SUMIF($B$27:$B$48,B18,$L$27:$L$48) -> 4 | Q18: =P18-G18 -> 0
A19: 14 | B19: ='BOM & COGS Ratio'!B16 -> FB-014 | C19: ='BOM & COGS Ratio'!C16 -> Cap Dust | D19: ='BOM & COGS Ratio'!E16 -> 2 | E19: ='BOM & COGS Ratio'!F16 -> pcs | F19: ='Factory Information'!A15 -> L10 | G19: ='BOM & COGS Ratio'!K16 -> 2 | H19: =IF(D19=0,0,G19/D19) -> 1 | I19: =IF($G$22=0,0,G19/$G$22) -> 0.0071326676 | J19: ='BOM & COGS Ratio'!J16 -> 0.0071 | K19: =ROUND(ABS(I19-J19),6) -> 3.3e-05 | L19: =SUMIF($B$27:$B$48,B19,$H$27:$H$48) -> 2 | M19: =ROUND(ABS(L19-G19),6) -> 0 | N19: ='Factory Information'!H15 -> 0.024 | O19: =G19/(1-N19) -> 2.0491803 | P19: =SUMIF($B$27:$B$48,B19,$L$27:$L$48) -> 2 | Q19: =P19-G19 -> 0
A20: 15 | B20: ='BOM & COGS Ratio'!B17 -> FB-015 | C20: ='BOM & COGS Ratio'!C17 -> Pads - Disc Kit | D20: ='BOM & COGS Ratio'!E17 -> 1 | E20: ='BOM & COGS Ratio'!F17 -> set | F20: ='Factory Information'!A16 -> L11 | G20: ='BOM & COGS Ratio'!K17 -> 30 | H20: =IF(D20=0,0,G20/D20) -> 30 | I20: =IF($G$22=0,0,G20/$G$22) -> 0.10699001 | J20: ='BOM & COGS Ratio'!J17 -> 0.107 | K20: =ROUND(ABS(I20-J20),6) -> 1e-05 | L20: =SUMIF($B$27:$B$48,B20,$H$27:$H$48) -> 30 | M20: =ROUND(ABS(L20-G20),6) -> 0 | N20: ='Factory Information'!H16 -> 0.03 | O20: =G20/(1-N20) -> 30.927835 | P20: =SUMIF($B$27:$B$48,B20,$L$27:$L$48) -> 30 | Q20: =P20-G20 -> 0
A21: 16 | B21: ='BOM & COGS Ratio'!B18 -> FB-016 | C21: ='BOM & COGS Ratio'!C18 -> Tube Hyd Front Distribution | D21: ='BOM & COGS Ratio'!E18 -> 1 | E21: ='BOM & COGS Ratio'!F18 -> pcs | F21: ='Factory Information'!A8 -> L4 | G21: ='BOM & COGS Ratio'!K18 -> 6 | H21: =IF(D21=0,0,G21/D21) -> 6 | I21: =IF($G$22=0,0,G21/$G$22) -> 0.021398003 | J21: ='BOM & COGS Ratio'!J18 -> 0.0214 | K21: =ROUND(ABS(I21-J21),6) -> 2e-06 | L21: =SUMIF($B$27:$B$48,B21,$H$27:$H$48) -> 6 | M21: =ROUND(ABS(L21-G21),6) -> 0 | N21: ='Factory Information'!H8 -> 0.025 | O21: =G21/(1-N21) -> 6.1538462 | P21: =SUMIF($B$27:$B$48,B21,$L$27:$L$48) -> 6 | Q21: =P21-G21 -> 0
B22: Total per set | G22: =SUM(G6:G21) -> 280.4 | I22: =SUM(I6:I21) -> 1 | J22: =SUM(J6:J21) -> 1 | K22: =MAX(K6:K21) -> 3.9e-05 | L22: =SUM(L6:L21) -> 280.4 | M22: =MAX(M6:M21) -> 0 | O22: =SUM(O6:O21) -> 288.50324 | P22: =SUM(P6:P21) -> 280.4 | Q22: =SUM(Q6:Q21) -> 0
B23: Source ratios are rounded to 4 decimals, so |Diff| up to 0.00005 is expected. Waste-adj. COGS = COGS / (1 - line waste rate) is a memo only (not in base COGS).
A25: 2. Level 2 - Raw-Material Decomposition of each Component (per set)
A26: # | B26: Parent Code | C26: Parent Name | D26: Material Code | E26: Material Name | F26: Share of Parent COGS (source) | G26: Parent COGS (USD/set) | H26: Material COGS (USD/set, source) | I26: Recalc = Share x Parent | J26: |Diff| recalc vs source | K26: Material Price Index (Scenario/Base) | L26: Scenario COGS (USD/set) | M26: Δ vs Base (USD/set) | N26: % of Total COGS (base)
A27: 1 | B27: ='BOM & COGS Ratio'!D19 -> FB-001 | C27: =INDEX($C$6:$C$21,MATCH(B27,$B$6:$B$21,0)) -> Hose Caliper Front LH | D27: ='BOM & COGS Ratio'!B19 -> RM-SS-TUBE-316L | E27: ='BOM & COGS Ratio'!C19 -> Stainless Steel | F27: ='BOM & COGS Ratio'!J19 -> 0.3961 | G27: =INDEX($G$6:$G$21,MATCH(B27,$B$6:$B$21,0)) -> 12 | H27: ='BOM & COGS Ratio'!K19 -> 4.7532 | I27: =F27*G27 -> 4.7532 | J27: =ROUND(ABS(I27-H27),6) -> 0 | K27: =INDEX('RM & Supplier Cost'!$K$6:$K$13,MATCH(D27,'RM & Supplier Cost'!$B$6:$B$13,0)) -> 1 | L27: =H27*K27 -> 4.7532 | M27: =L27-H27 -> 0 | N27: =IF($H$49=0,0,H27/$H$49) -> 0.016951498
A28: 2 | B28: ='BOM & COGS Ratio'!D22 -> FB-001 | C28: =INDEX($C$6:$C$21,MATCH(B28,$B$6:$B$21,0)) -> Hose Caliper Front LH | D28: ='BOM & COGS Ratio'!B22 -> RM-RUBBER-EPDM/NBR | E28: ='BOM & COGS Ratio'!C22 -> Synthetic Rubber | F28: ='BOM & COGS Ratio'!J22 -> 0.6039 | G28: =INDEX($G$6:$G$21,MATCH(B28,$B$6:$B$21,0)) -> 12 | H28: ='BOM & COGS Ratio'!K22 -> 7.2468 | I28: =F28*G28 -> 7.2468 | J28: =ROUND(ABS(I28-H28),6) -> 0 | K28: =INDEX('RM & Supplier Cost'!$K$6:$K$13,MATCH(D28,'RM & Supplier Cost'!$B$6:$B$13,0)) -> 1 | L28: =H28*K28 -> 7.2468 | M28: =L28-H28 -> 0 | N28: =IF($H$49=0,0,H28/$H$49) -> 0.025844508
A29: 3 | B29: ='BOM & COGS Ratio'!D23 -> FB-002 | C29: =INDEX($C$6:$C$21,MATCH(B29,$B$6:$B$21,0)) -> Hose Caliper Front RH | D29: ='BOM & COGS Ratio'!B23 -> RM-SS-TUBE-316L | E29: ='BOM & COGS Ratio'!C23 -> Stainless Steel | F29: ='BOM & COGS Ratio'!J23 -> 0.3961 | G29: =INDEX($G$6:$G$21,MATCH(B29,$B$6:$B$21,0)) -> 12 | H29: ='BOM & COGS Ratio'!K23 -> 4.7532 | I29: =F29*G29 -> 4.7532 | J29: =ROUND(ABS(I29-H29),6) -> 0 | K29: =INDEX('RM & Supplier Cost'!$K$6:$K$13,MATCH(D29,'RM & Supplier Cost'!$B$6:$B$13,0)) -> 1 | L29: =H29*K29 -> 4.7532 | M29: =L29-H29 -> 0 | N29: =IF($H$49=0,0,H29/$H$49) -> 0.016951498
A30: 4 | B30: ='BOM & COGS Ratio'!D26 -> FB-002 | C30: =INDEX($C$6:$C$21,MATCH(B30,$B$6:$B$21,0)) -> Hose Caliper Front RH | D30: ='BOM & COGS Ratio'!B26 -> RM-RUBBER-EPDM/NBR | E30: ='BOM & COGS Ratio'!C26 -> Synthetic Rubber | F30: ='BOM & COGS Ratio'!J26 -> 0.6039 | G30: =INDEX($G$6:$G$21,MATCH(B30,$B$6:$B$21,0)) -> 12 | H30: ='BOM & COGS Ratio'!K26 -> 7.2468 | I30: =F30*G30 -> 7.2468 | J30: =ROUND(ABS(I30-H30),6) -> 0 | K30: =INDEX('RM & Supplier Cost'!$K$6:$K$13,MATCH(D30,'RM & Supplier Cost'!$B$6:$B$13,0)) -> 1 | L30: =H30*K30 -> 7.2468 | M30: =L30-H30 -> 0 | N30: =IF($H$49=0,0,H30/$H$49) -> 0.025844508
A31: 5 | B31: ='BOM & COGS Ratio'!D27 -> FB-003 | C31: =INDEX($C$6:$C$21,MATCH(B31,$B$6:$B$21,0)) -> Seal - Brass Hydraulic | D31: ='BOM & COGS Ratio'!B27 -> RM-BRASS | E31: ='BOM & COGS Ratio'!C27 -> Brass | F31: ='BOM & COGS Ratio'!J27 -> 0.6431 | G31: =INDEX($G$6:$G$21,MATCH(B31,$B$6:$B$21,0)) -> 6 | H31: ='BOM & COGS Ratio'!K27 -> 3.8586 | I31: =F31*G31 -> 3.8586 | J31: =ROUND(ABS(I31-H31),6) -> 0 | K31: =INDEX('RM & Supplier Cost'!$K$6:$K$13,MATCH(D31,'RM & Supplier Cost'!$B$6:$B$13,0)) -> 1 | L31: =H31*K31 -> 3.8586 | M31: =L31-H31 -> 0 | N31: =IF($H$49=0,0,H31/$H$49) -> 0.013761056
A32: 6 | B32: ='BOM & COGS Ratio'!D28 -> FB-003 | C32: =INDEX($C$6:$C$21,MATCH(B32,$B$6:$B$21,0)) -> Seal - Brass Hydraulic | D32: ='BOM & COGS Ratio'!B28 -> RM-RUBBER-EPDM/NBR | E32: ='BOM & COGS Ratio'!C28 -> Synthetic Rubber | F32: ='BOM & COGS Ratio'!J28 -> 0.3569 | G32: =INDEX($G$6:$G$21,MATCH(B32,$B$6:$B$21,0)) -> 6 | H32: ='BOM & COGS Ratio'!K28 -> 2.1414 | I32: =F32*G32 -> 2.1414 | J32: =ROUND(ABS(I32-H32),6) -> 0 | K32: =INDEX('RM & Supplier Cost'!$K$6:$K$13,MATCH(D32,'RM & Supplier Cost'!$B$6:$B$13,0)) -> 1 | L32: =H32*K32 -> 2.1414 | M32: =L32-H32 -> 0 | N32: =IF($H$49=0,0,H32/$H$49) -> 0.0076369472
A33: 7 | B33: ='BOM & COGS Ratio'!D29 -> FB-004 | C33: =INDEX($C$6:$C$21,MATCH(B33,$B$6:$B$21,0)) -> Retain Clip Hose Frame Attach | D33: ='BOM & COGS Ratio'!B29 -> RM-STEEL-ALLOY | E33: ='BOM & COGS Ratio'!C29 -> Steel Alloy | F33: ='BOM & COGS Ratio'!J29 -> 1 | G33: =INDEX($G$6:$G$21,MATCH(B33,$B$6:$B$21,0)) -> 1 | H33: ='BOM & COGS Ratio'!K29 -> 1 | I33: =F33*G33 -> 1 | J33: =ROUND(ABS(I33-H33),6) -> 0 | K33: =INDEX('RM & Supplier Cost'!$K$6:$K$13,MATCH(D33,'RM & Supplier Cost'!$B$6:$B$13,0)) -> 1 | L33: =H33*K33 -> 1 | M33: =L33-H33 -> 0 | N33: =IF($H$49=0,0,H33/$H$49) -> 0.0035663338
A34: 8 | B34: ='BOM & COGS Ratio'!D31 -> FB-005 | C34: =INDEX($C$6:$C$21,MATCH(B34,$B$6:$B$21,0)) -> Stainless Brake Lines | D34: ='BOM & COGS Ratio'!B31 -> RM-SS-TUBE-316L | E34: ='BOM & COGS Ratio'!C31 -> Stainless Steel | F34: ='BOM & COGS Ratio'!J31 -> 1 | G34: =INDEX($G$6:$G$21,MATCH(B34,$B$6:$B$21,0)) -> 16 | H34: ='BOM & COGS Ratio'!K31 -> 16 | I34: =F34*G34 -> 16 | J34: =ROUND(ABS(I34-H34),6) -> 0 | K34: =INDEX('RM & Supplier Cost'!$K$6:$K$13,MATCH(D34,'RM & Supplier Cost'!$B$6:$B$13,0)) -> 1 | L34: =H34*K34 -> 16 | M34: =L34-H34 -> 0 | N34: =IF($H$49=0,0,H34/$H$49) -> 0.057061341
A35: 9 | B35: ='BOM & COGS Ratio'!D34 -> FB-006 | C35: =INDEX($C$6:$C$21,MATCH(B35,$B$6:$B$21,0)) -> Caliper Disc Front LH | D35: ='BOM & COGS Ratio'!B34 -> RM-STEEL-ALLOY | E35: ='BOM & COGS Ratio'!C34 -> Steel Alloy | F35: ='BOM & COGS Ratio'!J34 -> 1 | G35: =INDEX($G$6:$G$21,MATCH(B35,$B$6:$B$21,0)) -> 50 | H35: ='BOM & COGS Ratio'!K34 -> 50 | I35: =F35*G35 -> 50 | J35: =ROUND(ABS(I35-H35),6) -> 0 | K35: =INDEX('RM & Supplier Cost'!$K$6:$K$13,MATCH(D35,'RM & Supplier Cost'!$B$6:$B$13,0)) -> 1 | L35: =H35*K35 -> 50 | M35: =L35-H35 -> 0 | N35: =IF($H$49=0,0,H35/$H$49) -> 0.17831669
A36: 10 | B36: ='BOM & COGS Ratio'!D36 -> FB-007 | C36: =INDEX($C$6:$C$21,MATCH(B36,$B$6:$B$21,0)) -> Caliper Disc Front RH | D36: ='BOM & COGS Ratio'!B36 -> RM-STEEL-ALLOY | E36: ='BOM & COGS Ratio'!C36 -> Steel Alloy | F36: ='BOM & COGS Ratio'!J36 -> 1 | G36: =INDEX($G$6:$G$21,MATCH(B36,$B$6:$B$21,0)) -> 50 | H36: ='BOM & COGS Ratio'!K36 -> 50 | I36: =F36*G36 -> 50 | J36: =ROUND(ABS(I36-H36),6) -> 0 | K36: =INDEX('RM & Supplier Cost'!$K$6:$K$13,MATCH(D36,'RM & Supplier Cost'!$B$6:$B$13,0)) -> 1 | L36: =H36*K36 -> 50 | M36: =L36-H36 -> 0 | N36: =IF($H$49=0,0,H36/$H$49) -> 0.17831669
A37: 11 | B37: ='BOM & COGS Ratio'!D38 -> FB-008 | C37: =INDEX($C$6:$C$21,MATCH(B37,$B$6:$B$21,0)) -> Rotor Disc Brake | D37: ='BOM & COGS Ratio'!B38 -> RM-STEEL-ALLOY | E37: ='BOM & COGS Ratio'!C38 -> Steel Alloy | F37: ='BOM & COGS Ratio'!J38 -> 1 | G37: =INDEX($G$6:$G$21,MATCH(B37,$B$6:$B$21,0)) -> 50 | H37: ='BOM & COGS Ratio'!K38 -> 50 | I37: =F37*G37 -> 50 | J37: =ROUND(ABS(I37-H37),6) -> 0 | K37: =INDEX('RM & Supplier Cost'!$K$6:$K$13,MATCH(D37,'RM & Supplier Cost'!$B$6:$B$13,0)) -> 1 | L37: =H37*K37 -> 50 | M37: =L37-H37 -> 0 | N37: =IF($H$49=0,0,H37/$H$49) -> 0.17831669
A38: 12 | B38: ='BOM & COGS Ratio'!D40 -> FB-009 | C38: =INDEX($C$6:$C$21,MATCH(B38,$B$6:$B$21,0)) -> Bearing Inner Wheel | D38: ='BOM & COGS Ratio'!B40 -> RM-BEARING-STEEL | E38: ='BOM & COGS Ratio'!C40 -> Bearing Steel | F38: ='BOM & COGS Ratio'!J40 -> 1 | G38: =INDEX($G$6:$G$21,MATCH(B38,$B$6:$B$21,0)) -> 20 | H38: ='BOM & COGS Ratio'!K40 -> 20 | I38: =F38*G38 -> 20 | J38: =ROUND(ABS(I38-H38),6) -> 0 | K38: =INDEX('RM & Supplier Cost'!$K$6:$K$13,MATCH(D38,'RM & Supplier Cost'!$B$6:$B$13,0)) -> 1 | L38: =H38*K38 -> 20 | M38: =L38-H38 -> 0 | N38: =IF($H$49=0,0,H38/$H$49) -> 0.071326676
A39: 13 | B39: ='BOM & COGS Ratio'!D41 -> FB-010 | C39: =INDEX($C$6:$C$21,MATCH(B39,$B$6:$B$21,0)) -> Bearing Outer Wheel | D39: ='BOM & COGS Ratio'!B41 -> RM-BEARING-STEEL | E39: ='BOM & COGS Ratio'!C41 -> Bearing Steel | F39: ='BOM & COGS Ratio'!J41 -> 1 | G39: =INDEX($G$6:$G$21,MATCH(B39,$B$6:$B$21,0)) -> 20 | H39: ='BOM & COGS Ratio'!K41 -> 20 | I39: =F39*G39 -> 20 | J39: =ROUND(ABS(I39-H39),6) -> 0 | K39: =INDEX('RM & Supplier Cost'!$K$6:$K$13,MATCH(D39,'RM & Supplier Cost'!$B$6:$B$13,0)) -> 1 | L39: =H39*K39 -> 20 | M39: =L39-H39 -> 0 | N39: =IF($H$49=0,0,H39/$H$49) -> 0.071326676
A40: 14 | B40: ='BOM & COGS Ratio'!D42 -> FB-011 | C40: =INDEX($C$6:$C$21,MATCH(B40,$B$6:$B$21,0)) -> Washer Retainer Outer Bearing | D40: ='BOM & COGS Ratio'!B42 -> RM-STEEL-ALLOY | E40: ='BOM & COGS Ratio'!C42 -> Steel Alloy | F40: ='BOM & COGS Ratio'!J42 -> 1 | G40: =INDEX($G$6:$G$21,MATCH(B40,$B$6:$B$21,0)) -> 1 | H40: ='BOM & COGS Ratio'!K42 -> 1 | I40: =F40*G40 -> 1 | J40: =ROUND(ABS(I40-H40),6) -> 0 | K40: =INDEX('RM & Supplier Cost'!$K$6:$K$13,MATCH(D40,'RM & Supplier Cost'!$B$6:$B$13,0)) -> 1 | L40: =H40*K40 -> 1 | M40: =L40-H40 -> 0 | N40: =IF($H$49=0,0,H40/$H$49) -> 0.0035663338
A41: 15 | B41: ='BOM & COGS Ratio'!D44 -> FB-012 | C41: =INDEX($C$6:$C$21,MATCH(B41,$B$6:$B$21,0)) -> Cotter Key | D41: ='BOM & COGS Ratio'!B44 -> RM-STEEL-ALLOY | E41: ='BOM & COGS Ratio'!C44 -> Steel Alloy | F41: ='BOM & COGS Ratio'!J44 -> 1 | G41: =INDEX($G$6:$G$21,MATCH(B41,$B$6:$B$21,0)) -> 0.4 | H41: ='BOM & COGS Ratio'!K44 -> 0.4 | I41: =F41*G41 -> 0.4 | J41: =ROUND(ABS(I41-H41),6) -> 0 | K41: =INDEX('RM & Supplier Cost'!$K$6:$K$13,MATCH(D41,'RM & Supplier Cost'!$B$6:$B$13,0)) -> 1 | L41: =H41*K41 -> 0.4 | M41: =L41-H41 -> 0 | N41: =IF($H$49=0,0,H41/$H$49) -> 0.0014265335
A42: 16 | B42: ='BOM & COGS Ratio'!D46 -> FB-013 | C42: =INDEX($C$6:$C$21,MATCH(B42,$B$6:$B$21,0)) -> Seal Grease | D42: ='BOM & COGS Ratio'!B46 -> RM-GREASE | E42: ='BOM & COGS Ratio'!C46 -> High Temp Grease | F42: ='BOM & COGS Ratio'!J46 -> 0.6954 | G42: =INDEX($G$6:$G$21,MATCH(B42,$B$6:$B$21,0)) -> 4 | H42: ='BOM & COGS Ratio'!K46 -> 2.7816 | I42: =F42*G42 -> 2.7816 | J42: =ROUND(ABS(I42-H42),6) -> 0 | K42: =INDEX('RM & Supplier Cost'!$K$6:$K$13,MATCH(D42,'RM & Supplier Cost'!$B$6:$B$13,0)) -> 1 | L42: =H42*K42 -> 2.7816 | M42: =L42-H42 -> 0 | N42: =IF($H$49=0,0,H42/$H$49) -> 0.0099201141
...

Sheet RM & Supplier Cost
A1: Raw-Material & Supplier Cost Allocation (per set, monthly, annual)
A2: Multi-sourced materials are split by value share = supply ratio x unit price / Σ(supply ratio x unit price). Scenario material cost = Base x (weighted scenario price / weighted base price).
A4: 1. Cost by Raw Material (per set)
A5: # | B5: Material Code | C5: Material Name | D5: # BOM Lines | E5: # Suppliers | F5: Σ Supply Ratio | G5: Base COGS (USD/set) | H5: % of Total COGS | I5: Wtd Avg Base Price (USD/pc) | J5: Wtd Avg Scenario Price (USD/pc) | K5: Price Index (Scenario/Base) | L5: Scenario COGS (USD/set) | M5: Δ vs Base (USD/set) | N5: Implied Purchase Qty (pcs/set) | O5: Monthly Requirement (pcs)
A6: 1 | B6: ='Supplier Profile'!A3 -> RM-SS-TUBE-316L | C6: ='Supplier Profile'!B3 -> Stainless Steel | D6: =COUNTIF('BOM Cost Build-up'!$D$27:$D$48,B6) -> 4 | E6: =COUNTIF(Assumptions!$B$20:$B$30,B6) -> 3 | F6: =SUMIF(Assumptions!$B$20:$B$30,B6,Assumptions!$F$20:$F$30) -> 1 | G6: =SUMIF('BOM Cost Build-up'!$D$27:$D$48,B6,'BOM Cost Build-up'!$H$27:$H$48) -> 31.5064 | H6: =IF($G$14=0,0,G6/$G$14) -> 0.11236234 | I6: =IF(F6=0,0,SUMPRODUCT((Assumptions!$B$20:$B$30=B6)*Assumptions!$F$20:$F$30*Assumptions!$G$20:$G$30)/F6) -> 4.155 | J6: =IF(F6=0,0,SUMPRODUCT((Assumptions!$B$20:$B$30=B6)*Assumptions!$F$20:$F$30*Assumptions!$I$20:$I$30)/F6) -> 4.155 | K6: =IF(I6=0,1,J6/I6) -> 1 | L6: =G6*K6 -> 31.5064 | M6: =L6-G6 -> 0 | N6: =IF(I6=0,0,G6/I6) -> 7.5827677 | O6: =N6*Assumptions!$C$15 -> 154688.46
A7: 2 | B7: ='Supplier Profile'!A6 -> RM-RUBBER-EPDM/NBR | C7: ='Supplier Profile'!B6 -> Synthetic Rubber | D7: =COUNTIF('BOM Cost Build-up'!$D$27:$D$48,B7) -> 5 | E7: =COUNTIF(Assumptions!$B$20:$B$30,B7) -> 1 | F7: =SUMIF(Assumptions!$B$20:$B$30,B7,Assumptions!$F$20:$F$30) -> 1 | G7: =SUMIF('BOM Cost Build-up'!$D$27:$D$48,B7,'BOM Cost Build-up'!$H$27:$H$48) -> 18.6652 | H7: =IF($G$14=0,0,G7/$G$14) -> 0.066566334 | I7: =IF(F7=0,0,SUMPRODUCT((Assumptions!$B$20:$B$30=B7)*Assumptions!$F$20:$F$30*Assumptions!$G$20:$G$30)/F7) -> 2.9 | J7: =IF(F7=0,0,SUMPRODUCT((Assumptions!$B$20:$B$30=B7)*Assumptions!$F$20:$F$30*Assumptions!$I$20:$I$30)/F7) -> 2.9 | K7: =IF(I7=0,1,J7/I7) -> 1 | L7: =G7*K7 -> 18.6652 | M7: =L7-G7 -> 0 | N7: =IF(I7=0,0,G7/I7) -> 6.4362759 | O7: =N7*Assumptions!$C$15 -> 131300.03
A8: 3 | B8: ='Supplier Profile'!A7 -> RM-BRASS | C8: ='Supplier Profile'!B7 -> Brass | D8: =COUNTIF('BOM Cost Build-up'!$D$27:$D$48,B8) -> 1 | E8: =COUNTIF(Assumptions!$B$20:$B$30,B8) -> 1 | F8: =SUMIF(Assumptions!$B$20:$B$30,B8,Assumptions!$F$20:$F$30) -> 1 | G8: =SUMIF('BOM Cost Build-up'!$D$27:$D$48,B8,'BOM Cost Build-up'!$H$27:$H$48) -> 3.8586 | H8: =IF($G$14=0,0,G8/$G$14) -> 0.013761056 | I8: =IF(F8=0,0,SUMPRODUCT((Assumptions!$B$20:$B$30=B8)*Assumptions!$F$20:$F$30*Assumptions!$G$20:$G$30)/F8) -> 3.6 | J8: =IF(F8=0,0,SUMPRODUCT((Assumptions!$B$20:$B$30=B8)*Assumptions!$F$20:$F$30*Assumptions!$I$20:$I$30)/F8) -> 3.6 | K8: =IF(I8=0,1,J8/I8) -> 1 | L8: =G8*K8 -> 3.8586 | M8: =L8-G8 -> 0 | N8: =IF(I8=0,0,G8/I8) -> 1.0718333 | O8: =N8*Assumptions!$C$15 -> 21865.4
A9: 4 | B9: ='Supplier Profile'!A8 -> RM-STEEL-ALLOY | C9: ='Supplier Profile'!B8 -> Steel Alloy | D9: =COUNTIF('BOM Cost Build-up'!$D$27:$D$48,B9) -> 7 | E9: =COUNTIF(Assumptions!$B$20:$B$30,B9) -> 2 | F9: =SUMIF(Assumptions!$B$20:$B$30,B9,Assumptions!$F$20:$F$30) -> 1 | G9: =SUMIF('BOM Cost Build-up'!$D$27:$D$48,B9,'BOM Cost Build-up'!$H$27:$H$48) -> 161.454 | H9: =IF($G$14=0,0,G9/$G$14) -> 0.57579886 | I9: =IF(F9=0,0,SUMPRODUCT((Assumptions!$B$20:$B$30=B9)*Assumptions!$F$20:$F$30*Assumptions!$G$20:$G$30)/F9) -> 8.46 | J9: =IF(F9=0,0,SUMPRODUCT((Assumptions!$B$20:$B$30=B9)*Assumptions!$F$20:$F$30*Assumptions!$I$20:$I$30)/F9) -> 8.46 | K9: =IF(I9=0,1,J9/I9) -> 1 | L9: =G9*K9 -> 161.454 | M9: =L9-G9 -> 0 | N9: =IF(I9=0,0,G9/I9) -> 19.084397 | O9: =N9*Assumptions!$C$15 -> 389321.7
A10: 5 | B10: ='Supplier Profile'!A10 -> RM-BEARING-STEEL | C10: ='Supplier Profile'!B10 -> Bearing Steel | D10: =COUNTIF('BOM Cost Build-up'!$D$27:$D$48,B10) -> 2 | E10: =COUNTIF(Assumptions!$B$20:$B$30,B10) -> 1 | F10: =SUMIF(Assumptions!$B$20:$B$30,B10,Assumptions!$F$20:$F$30) -> 1 | G10: =SUMIF('BOM Cost Build-up'!$D$27:$D$48,B10,'BOM Cost Build-up'!$H$27:$H$48) -> 40 | H10: =IF($G$14=0,0,G10/$G$14) -> 0.14265335 | I10: =IF(F10=0,0,SUMPRODUCT((Assumptions!$B$20:$B$30=B10)*Assumptions!$F$20:$F$30*Assumptions!$G$20:$G$30)/F10) -> 9.5 | J10: =IF(F10=0,0,SUMPRODUCT((Assumptions!$B$20:$B$30=B10)*Assumptions!$F$20:$F$30*Assumptions!$I$20:$I$30)/F10) -> 9.5 | K10: =IF(I10=0,1,J10/I10) -> 1 | L10: =G10*K10 -> 40 | M10: =L10-G10 -> 0 | N10: =IF(I10=0,0,G10/I10) -> 4.2105263 | O10: =N10*Assumptions!$C$15 -> 85894.737
A11: 6 | B11: ='Supplier Profile'!A11 -> RM-GREASE | C11: ='Supplier Profile'!B11 -> High Temp Grease | D11: =COUNTIF('BOM Cost Build-up'!$D$27:$D$48,B11) -> 1 | E11: =COUNTIF(Assumptions!$B$20:$B$30,B11) -> 1 | F11: =SUMIF(Assumptions!$B$20:$B$30,B11,Assumptions!$F$20:$F$30) -> 1 | G11: =SUMIF('BOM Cost Build-up'!$D$27:$D$48,B11,'BOM Cost Build-up'!$H$27:$H$48) -> 2.7816 | H11: =IF($G$14=0,0,G11/$G$14) -> 0.0099201141 | I11: =IF(F11=0,0,SUMPRODUCT((Assumptions!$B$20:$B$30=B11)*Assumptions!$F$20:$F$30*Assumptions!$G$20:$G$30)/F11) -> 2.5 | J11: =IF(F11=0,0,SUMPRODUCT((Assumptions!$B$20:$B$30=B11)*Assumptions!$F$20:$F$30*Assumptions!$I$20:$I$30)/F11) -> 2.5 | K11: =IF(I11=0,1,J11/I11) -> 1 | L11: =G11*K11 -> 2.7816 | M11: =L11-G11 -> 0 | N11: =IF(I11=0,0,G11/I11) -> 1.11264 | O11: =N11*Assumptions!$C$15 -> 22697.856
A12: 7 | B12: ='Supplier Profile'!A12 -> RM-PLASTIC-POM | C12: ='Supplier Profile'!B12 -> Engineering Plastic | D12: =COUNTIF('BOM Cost Build-up'!$D$27:$D$48,B12) -> 1 | E12: =COUNTIF(Assumptions!$B$20:$B$30,B12) -> 1 | F12: =SUMIF(Assumptions!$B$20:$B$30,B12,Assumptions!$F$20:$F$30) -> 1 | G12: =SUMIF('BOM Cost Build-up'!$D$27:$D$48,B12,'BOM Cost Build-up'!$H$27:$H$48) -> 1.1882 | H12: =IF($G$14=0,0,G12/$G$14) -> 0.0042375178 | I12: =IF(F12=0,0,SUMPRODUCT((Assumptions!$B$20:$B$30=B12)*Assumptions!$F$20:$F$30*Assumptions!$G$20:$G$30)/F12) -> 1.1 | J12: =IF(F12=0,0,SUMPRODUCT((Assumptions!$B$20:$B$30=B12)*Assumptions!$F$20:$F$30*Assumptions!$I$20:$I$30)/F12) -> 1.1 | K12: =IF(I12=0,1,J12/I12) -> 1 | L12: =G12*K12 -> 1.1882 | M12: =L12-G12 -> 0 | N12: =IF(I12=0,0,G12/I12) -> 1.0801818 | O12: =N12*Assumptions!$C$15 -> 22035.709
A13: 8 | B13: ='Supplier Profile'!A13 -> RM-FRICTION-MAT | C13: ='Supplier Profile'!B13 -> Friction Material | D13: =COUNTIF('BOM Cost Build-up'!$D$27:$D$48,B13) -> 1 | E13: =COUNTIF(Assumptions!$B$20:$B$30,B13) -> 1 | F13: =SUMIF(Assumptions!$B$20:$B$30,B13,Assumptions!$F$20:$F$30) -> 1 | G13: =SUMIF('BOM Cost Build-up'!$D$27:$D$48,B13,'BOM Cost Build-up'!$H$27:$H$48) -> 20.946 | H13: =IF($G$14=0,0,G13/$G$14) -> 0.074700428 | I13: =IF(F13=0,0,SUMPRODUCT((Assumptions!$B$20:$B$30=B13)*Assumptions!$F$20:$F$30*Assumptions!$G$20:$G$30)/F13) -> 19.5 | J13: =IF(F13=0,0,SUMPRODUCT((Assumptions!$B$20:$B$30=B13)*Assumptions!$F$20:$F$30*Assumptions!$I$20:$I$30)/F13) -> 19.5 | K13: =IF(I13=0,1,J13/I13) -> 1 | L13: =G13*K13 -> 20.946 | M13: =L13-G13 -> 0 | N13: =IF(I13=0,0,G13/I13) -> 1.0741538 | O13: =N13*Assumptions!$C$15 -> 21912.738
B14: Total | D14: =SUM(D6:D13) -> 22 | G14: =SUM(G6:G13) -> 280.4 | H14: =SUM(H6:H13) -> 1 | L14: =SUM(L6:L13) -> 280.4 | M14: =SUM(M6:M13) -> 0
B15: Implied purchase qty = Base COGS / weighted average unit price (memo: translates the BOM cost into pieces bought at Supplier Profile prices).
A16: 2. Cost by Supplier x Material (per set, monthly, annual)
A17: # | B17: Supplier | C17: Origin | D17: Material Code | E17: Material Name | F17: Supply Ratio | G17: Base Unit Price (USD/pc) | H17: Value Share in Material | I17: Base COGS (USD/set) | J17: % of Total COGS | K17: Base Monthly Spend (USD) | L17: Base Annual Spend (USD) | M17: Price Change vs Base | N17: Scenario COGS (USD/set) | O17: Δ vs Base (USD/set) | P17: Implied Monthly Qty (pcs)
A18: 1 | B18: =Assumptions!D20 -> SteelCorp Ltd. | C18: =Assumptions!E20 -> Japan | D18: =Assumptions!B20 -> RM-SS-TUBE-316L | E18: =Assumptions!C20 -> Stainless Steel | F18: =Assumptions!F20 -> 0.4 | G18: =Assumptions!G20 -> 4.2 | H18: =IFERROR(F18*G18/SUMPRODUCT(($D$18:$D$28=D18)*$F$18:$F$28*$G$18:$G$28),0) -> 0.40433213 | I18: =INDEX($G$6:$G$13,MATCH(D18,$B$6:$B$13,0))*H18 -> 12.73905 | J18: =IF($I$29=0,0,I18/$I$29) -> 0.045431704 | K18: =I18*Assumptions!$C$15 -> 259876.62 | L18: =I18*Assumptions!$C$16 -> 3118519.4 | M18: =Assumptions!H20 -> 0 | N18: =I18*(1+M18) -> 12.73905 | O18: =N18-I18 -> 0 | P18: =INDEX($O$6:$O$13,MATCH(D18,$B$6:$B$13,0))*F18 -> 61875.385
A19: 2 | B19: =Assumptions!D21 -> Nihon Metal Works | C19: =Assumptions!E21 -> Japan | D19: =Assumptions!B21 -> RM-SS-TUBE-316L | E19: =Assumptions!C21 -> Stainless Steel | F19: =Assumptions!F21 -> 0.3 | G19: =Assumptions!G21 -> 4.1 | H19: =IFERROR(F19*G19/SUMPRODUCT(($D$18:$D$28=D19)*$F$18:$F$28*$G$18:$G$28),0) -> 0.29602888 | I19: =INDEX($G$6:$G$13,MATCH(D19,$B$6:$B$13,0))*H19 -> 9.3268043 | J19: =IF($I$29=0,0,I19/$I$29) -> 0.033262498 | K19: =I19*Assumptions!$C$15 -> 190266.81 | L19: =I19*Assumptions!$C$16 -> 2283201.7 | M19: =Assumptions!H21 -> 0 | N19: =I19*(1+M19) -> 9.3268043 | O19: =N19-I19 -> 0 | P19: =INDEX($O$6:$O$13,MATCH(D19,$B$6:$B$13,0))*F19 -> 46406.539
A20: 3 | B20: =Assumptions!D22 -> GlobalSteel Industries | C20: =Assumptions!E22 -> South Korea | D20: =Assumptions!B22 -> RM-SS-TUBE-316L | E20: =Assumptions!C22 -> Stainless Steel | F20: =Assumptions!F22 -> 0.3 | G20: =Assumptions!G22 -> 4.15 | H20: =IFERROR(F20*G20/SUMPRODUCT(($D$18:$D$28=D20)*$F$18:$F$28*$G$18:$G$28),0) -> 0.29963899 | I20: =INDEX($G$6:$G$13,MATCH(D20,$B$6:$B$13,0))*H20 -> 9.4405458 | J20: =IF($I$29=0,0,I20/$I$29) -> 0.033668138 | K20: =I20*Assumptions!$C$15 -> 192587.14 | L20: =I20*Assumptions!$C$16 -> 2311045.6 | M20: =Assumptions!H22 -> 0 | N20: =I20*(1+M20) -> 9.4405458 | O20: =N20-I20 -> 0 | P20: =INDEX($O$6:$O$13,MATCH(D20,$B$6:$B$13,0))*F20 -> 46406.539
A21: 4 | B21: =Assumptions!D23 -> PolyRubber Inc. | C21: =Assumptions!E23 -> Vietnam | D21: =Assumptions!B23 -> RM-RUBBER-EPDM/NBR | E21: =Assumptions!C23 -> Synthetic Rubber | F21: =Assumptions!F23 -> 1 | G21: =Assumptions!G23 -> 2.9 | H21: =IFERROR(F21*G21/SUMPRODUCT(($D$18:$D$28=D21)*$F$18:$F$28*$G$18:$G$28),0) -> 1 | I21: =INDEX($G$6:$G$13,MATCH(D21,$B$6:$B$13,0))*H21 -> 18.6652 | J21: =IF($I$29=0,0,I21/$I$29) -> 0.066566334 | K21: =I21*Assumptions!$C$15 -> 380770.08 | L21: =I21*Assumptions!$C$16 -> 4569241 | M21: =Assumptions!H23 -> 0 | N21: =I21*(1+M21) -> 18.6652 | O21: =N21-I21 -> 0 | P21: =INDEX($O$6:$O$13,MATCH(D21,$B$6:$B$13,0))*F21 -> 131300.03
A22: 5 | B22: =Assumptions!D24 -> MetalWorks Co. | C22: =Assumptions!E24 -> Vietnam | D22: =Assumptions!B24 -> RM-BRASS | E22: =Assumptions!C24 -> Brass | F22: =Assumptions!F24 -> 1 | G22: =Assumptions!G24 -> 3.6 | H22: =IFERROR(F22*G22/SUMPRODUCT(($D$18:$D$28=D22)*$F$18:$F$28*$G$18:$G$28),0) -> 1 | I22: =INDEX($G$6:$G$13,MATCH(D22,$B$6:$B$13,0))*H22 -> 3.8586 | J22: =IF($I$29=0,0,I22/$I$29) -> 0.013761056 | K22: =I22*Assumptions!$C$15 -> 78715.44 | L22: =I22*Assumptions!$C$16 -> 944585.28 | M22: =Assumptions!H24 -> 0 | N22: =I22*(1+M22) -> 3.8586 | O22: =N22-I22 -> 0 | P22: =INDEX($O$6:$O$13,MATCH(D22,$B$6:$B$13,0))*F22 -> 21865.4
A23: 6 | B23: =Assumptions!D25 -> SteelCorp Ltd. | C23: =Assumptions!E25 -> Japan | D23: =Assumptions!B25 -> RM-STEEL-ALLOY | E23: =Assumptions!C25 -> Steel Alloy | F23: =Assumptions!F25 -> 0.6 | G23: =Assumptions!G25 -> 8.5 | H23: =IFERROR(F23*G23/SUMPRODUCT(($D$18:$D$28=D23)*$F$18:$F$28*$G$18:$G$28),0) -> 0.60283688 | I23: =INDEX($G$6:$G$13,MATCH(D23,$B$6:$B$13,0))*H23 -> 97.330426 | J23: =IF($I$29=0,0,I23/$I$29) -> 0.34711279 | K23: =I23*Assumptions!$C$15 -> 1985540.7 | L23: =I23*Assumptions!$C$16 -> 23826488 | M23: =Assumptions!H25 -> 0 | N23: =I23*(1+M23) -> 97.330426 | O23: =N23-I23 -> 0 | P23: =INDEX($O$6:$O$13,MATCH(D23,$B$6:$B$13,0))*F23 -> 233593.02
A24: 7 | B24: =Assumptions!D26 -> GlobalSteel Industries | C24: =Assumptions!E26 -> South Korea | D24: =Assumptions!B26 -> RM-STEEL-ALLOY | E24: =Assumptions!C26 -> Steel Alloy | F24: =Assumptions!F26 -> 0.4 | G24: =Assumptions!G26 -> 8.4 | H24: =IFERROR(F24*G24/SUMPRODUCT(($D$18:$D$28=D24)*$F$18:$F$28*$G$18:$G$28),0) -> 0.39716312 | I24: =INDEX($G$6:$G$13,MATCH(D24,$B$6:$B$13,0))*H24 -> 64.123574 | J24: =IF($I$29=0,0,I24/$I$29) -> 0.22868607 | K24: =I24*Assumptions!$C$15 -> 1308120.9 | L24: =I24*Assumptions!$C$16 -> 15697451 | M24: =Assumptions!H26 -> 0 | N24: =I24*(1+M24) -> 64.123574 | O24: =N24-I24 -> 0 | P24: =INDEX($O$6:$O$13,MATCH(D24,$B$6:$B$13,0))*F24 -> 155728.68
A25: 8 | B25: =Assumptions!D27 -> SteelCorp Ltd. | C25: =Assumptions!E27 -> Japan | D25: =Assumptions!B27 -> RM-BEARING-STEEL | E25: =Assumptions!C27 -> Bearing Steel | F25: =Assumptions!F27 -> 1 | G25: =Assumptions!G27 -> 9.5 | H25: =IFERROR(F25*G25/SUMPRODUCT(($D$18:$D$28=D25)*$F$18:$F$28*$G$18:$G$28),0) -> 1 | I25: =INDEX($G$6:$G$13,MATCH(D25,$B$6:$B$13,0))*H25 -> 40 | J25: =IF($I$29=0,0,I25/$I$29) -> 0.14265335 | K25: =I25*Assumptions!$C$15 -> 816000 | L25: =I25*Assumptions!$C$16 -> 9792000 | M25: =Assumptions!H27 -> 0 | N25: =I25*(1+M25) -> 40 | O25: =N25-I25 -> 0 | P25: =INDEX($O$6:$O$13,MATCH(D25,$B$6:$B$13,0))*F25 -> 85894.737
A26: 9 | B26: =Assumptions!D28 -> ChemLube Ltd. | C26: =Assumptions!E28 -> Vietnam | D26: =Assumptions!B28 -> RM-GREASE | E26: =Assumptions!C28 -> High Temp Grease | F26: =Assumptions!F28 -> 1 | G26: =Assumptions!G28 -> 2.5 | H26: =IFERROR(F26*G26/SUMPRODUCT(($D$18:$D$28=D26)*$F$18:$F$28*$G$18:$G$28),0) -> 1 | I26: =INDEX($G$6:$G$13,MATCH(D26,$B$6:$B$13,0))*H26 -> 2.7816 | J26: =IF($I$29=0,0,I26/$I$29) -> 0.0099201141 | K26: =I26*Assumptions!$C$15 -> 56744.64 | L26: =I26*Assumptions!$C$16 -> 680935.68 | M26: =Assumptions!H28 -> 0 | N26: =I26*(1+M26) -> 2.7816 | O26: =N26-I26 -> 0 | P26: =INDEX($O$6:$O$13,MATCH(D26,$B$6:$B$13,0))*F26 -> 22697.856
A27: 10 | B27: =Assumptions!D29 -> PolyRubber Inc. | C27: =Assumptions!E29 -> Vietnam | D27: =Assumptions!B29 -> RM-PLASTIC-POM | E27: =Assumptions!C29 -> Engineering Plastic | F27: =Assumptions!F29 -> 1 | G27: =Assumptions!G29 -> 1.1 | H27: =IFERROR(F27*G27/SUMPRODUCT(($D$18:$D$28=D27)*$F$18:$F$28*$G$18:$G$28),0) -> 1 | I27: =INDEX($G$6:$G$13,MATCH(D27,$B$6:$B$13,0))*H27 -> 1.1882 | J27: =IF($I$29=0,0,I27/$I$29) -> 0.0042375178 | K27: =I27*Assumptions!$C$15 -> 24239.28 | L27: =I27*Assumptions!$C$16 -> 290871.36 | M27: =Assumptions!H29 -> 0 | N27: =I27*(1+M27) -> 1.1882 | O27: =N27-I27 -> 0 | P27: =INDEX($O$6:$O$13,MATCH(D27,$B$6:$B$13,0))*F27 -> 22035.709
A28: 11 | B28: =Assumptions!D30 -> FrictionTech Co. | C28: =Assumptions!E30 -> Japan | D28: =Assumptions!B30 -> RM-FRICTION-MAT | E28: =Assumptions!C30 -> Friction Material | F28: =Assumptions!F30 -> 1 | G28: =Assumptions!G30 -> 19.5 | H28: =IFERROR(F28*G28/SUMPRODUCT(($D$18:$D$28=D28)*$F$18:$F$28*$G$18:$G$28),0) -> 1 | I28: =INDEX($G$6:$G$13,MATCH(D28,$B$6:$B$13,0))*H28 -> 20.946 | J28: =IF($I$29=0,0,I28/$I$29) -> 0.074700428 | K28: =I28*Assumptions!$C$15 -> 427298.4 | L28: =I28*Assumptions!$C$16 -> 5127580.8 | M28: =Assumptions!H30 -> 0 | N28: =I28*(1+M28) -> 20.946 | O28: =N28-I28 -> 0 | P28: =INDEX($O$6:$O$13,MATCH(D28,$B$6:$B$13,0))*F28 -> 21912.738
B29: Total | I29: =SUM(I18:I28) -> 280.4 | J29: =SUM(J18:J28) -> 1 | K29: =SUM(K18:K28) -> 5720160 | L29: =SUM(L18:L28) -> 68641920 | N29: =SUM(N18:N28) -> 280.4 | O29: =SUM(O18:O28) -> 0
A31: 3. Cost by Supplier
A32: # | B32: Supplier | C32: Origin | D32: # Materials Supplied | E32: Base COGS (USD/set) | F32: % of Total COGS | G32: Base Monthly Spend (USD) | H32: Base Annual Spend (USD) | I32: Scenario COGS (USD/set) | J32: Δ vs Base (USD/set) | K32: Δ vs Base (%)
A33: 1 | B33: ='Supplier Profile'!C3 -> SteelCorp Ltd. | C33: =INDEX($C$18:$C$28,MATCH(B33,$B$18:$B$28,0)) -> Japan | D33: =COUNTIF($B$18:$B$28,B33) -> 3 | E33: =SUMIF($B$18:$B$28,B33,$I$18:$I$28) -> 150.06948 | F33: =IF($E$40=0,0,E33/$E$40) -> 0.53519784 | G33: =SUMIF($B$18:$B$28,B33,$K$18:$K$28) -> 3061417.3 | H33: =SUMIF($B$18:$B$28,B33,$L$18:$L$28) -> 36737008 | I33: =SUMIF($B$18:$B$28,B33,$N$18:$N$28) -> 150.06948 | J33: =I33-E33 -> 0 | K33: =IF(E33=0,0,J33/E33) -> 0
A34: 2 | B34: ='Supplier Profile'!C4 -> Nihon Metal Works | C34: =INDEX($C$18:$C$28,MATCH(B34,$B$18:$B$28,0)) -> Japan | D34: =COUNTIF($B$18:$B$28,B34) -> 1 | E34: =SUMIF($B$18:$B$28,B34,$I$18:$I$28) -> 9.3268043 | F34: =IF($E$40=0,0,E34/$E$40) -> 0.033262498 | G34: =SUMIF($B$18:$B$28,B34,$K$18:$K$28) -> 190266.81 | H34: =SUMIF($B$18:$B$28,B34,$L$18:$L$28) -> 2283201.7 | I34: =SUMIF($B$18:$B$28,B34,$N$18:$N$28) -> 9.3268043 | J34: =I34-E34 -> 0 | K34: =IF(E34=0,0,J34/E34) -> 0
A35: 3 | B35: ='Supplier Profile'!C5 -> GlobalSteel Industries | C35: =INDEX($C$18:$C$28,MATCH(B35,$B$18:$B$28,0)) -> South Korea | D35: =COUNTIF($B$18:$B$28,B35) -> 2 | E35: =SUMIF($B$18:$B$28,B35,$I$18:$I$28) -> 73.56412 | F35: =IF($E$40=0,0,E35/$E$40) -> 0.26235421 | G35: =SUMIF($B$18:$B$28,B35,$K$18:$K$28) -> 1500708.1 | H35: =SUMIF($B$18:$B$28,B35,$L$18:$L$28) -> 18008497 | I35: =SUMIF($B$18:$B$28,B35,$N$18:$N$28) -> 73.56412 | J35: =I35-E35 -> 0 | K35: =IF(E35=0,0,J35/E35) -> 0
A36: 4 | B36: ='Supplier Profile'!C6 -> PolyRubber Inc. | C36: =INDEX($C$18:$C$28,MATCH(B36,$B$18:$B$28,0)) -> Vietnam | D36: =COUNTIF($B$18:$B$28,B36) -> 2 | E36: =SUMIF($B$18:$B$28,B36,$I$18:$I$28) -> 19.8534 | F36: =IF($E$40=0,0,E36/$E$40) -> 0.070803852 | G36: =SUMIF($B$18:$B$28,B36,$K$18:$K$28) -> 405009.36 | H36: =SUMIF($B$18:$B$28,B36,$L$18:$L$28) -> 4860112.3 | I36: =SUMIF($B$18:$B$28,B36,$N$18:$N$28) -> 19.8534 | J36: =I36-E36 -> 0 | K36: =IF(E36=0,0,J36/E36) -> 0
A37: 5 | B37: ='Supplier Profile'!C7 -> MetalWorks Co. | C37: =INDEX($C$18:$C$28,MATCH(B37,$B$18:$B$28,0)) -> Vietnam | D37: =COUNTIF($B$18:$B$28,B37) -> 1 | E37: =SUMIF($B$18:$B$28,B37,$I$18:$I$28) -> 3.8586 | F37: =IF($E$40=0,0,E37/$E$40) -> 0.013761056 | G37: =SUMIF($B$18:$B$28,B37,$K$18:$K$28) -> 78715.44 | H37: =SUMIF($B$18:$B$28,B37,$L$18:$L$28) -> 944585.28 | I37: =SUMIF($B$18:$B$28,B37,$N$18:$N$28) -> 3.8586 | J37: =I37-E37 -> 0 | K37: =IF(E37=0,0,J37/E37) -> 0
A38: 6 | B38: ='Supplier Profile'!C11 -> ChemLube Ltd. | C38: =INDEX($C$18:$C$28,MATCH(B38,$B$18:$B$28,0)) -> Vietnam | D38: =COUNTIF($B$18:$B$28,B38) -> 1 | E38: =SUMIF($B$18:$B$28,B38,$I$18:$I$28) -> 2.7816 | F38: =IF($E$40=0,0,E38/$E$40) -> 0.0099201141 | G38: =SUMIF($B$18:$B$28,B38,$K$18:$K$28) -> 56744.64 | H38: =SUMIF($B$18:$B$28,B38,$L$18:$L$28) -> 680935.68 | I38: =SUMIF($B$18:$B$28,B38,$N$18:$N$28) -> 2.7816 | J38: =I38-E38 -> 0 | K38: =IF(E38=0,0,J38/E38) -> 0
